Workbook

Sheet Pricing Worksheet
B2: Project name | E2: Project address | H2: Quote # | K2: Person Quoting | N2: Person who checked quote | Q2: 3.20.25 - 182 Robinson St - Mike Vetzal - Glass Flooring Systems Proposal #17717 Distributor Pricing | R2: Residential
B3: Contact | E3: Contact address | H3: Contact phone | K3: Contact email | L3: mailto:mvetzal@bapgroup.ca | R3: Commercial
B4: Project Type | E4: Architect | H4: Homeowner | K4: Drafter/Designer
B5: Fill in yellow cells only. All other cells will calculate automatically
B6: Surfaces | C6: Cost/Unit $ | D6: =B113 | G6: =B114 | J6: =B115 | M6: =B116 | P6: =B117 | S6: =B118 | V6: =B119 | Y6: =B120 | AB6: =B121 | AE6: =B122 | AH6: Subtotal $
C7: Do not erase | E7: Qty | F7: Price | H7: Qty | I7: Price | K7: Qty | L7: Price | N7: Qty | O7: Price | Q7: Qty | R7: Price | T7: Qty | U7: Price | W7: Qty | X7: Price | Z7: Qty | AA7: Price | AC7: Qty | AD7: Price | AF7: Qty | AG7: Price
B8: Glass
B9: Glass - no IGU | C9: 66 | E9: =IF(D9="y",$H$113,0) | F9: =E9*$C9 | H9: =IF(G9="y",$H$114,0) | I9: =H9*$C9 | K9: =IF(J9="y",$H$115,0) | L9: =K9*$C9 | N9: =IF(M9="y",$H$116,0) | O9: =N9*$C9 | Q9: =IF(P9="y",$H$117,0) | R9: =Q9*$C9 | T9: =IF(S9="y",$H$118,0) | U9: =T9*$C9 | W9: =IF(V9="y",$H$119,0) | X9: =W9*$C9 | Z9: =IF(Y9="y",$H$120,0) | AA9: =Z9*$C9 | AC9: =IF(AB9="y",$H$121,0) | AD9: =AC9*$C9 | AF9: =IF(AE9="y",$H$122,0) | AG9: =AF9*$C9 | AH9: =SUM(F9+I9+L9+O9+R9+U9+X9+AA9+AD9+AG9)
B10: Glass - with IGU | C10: 112 | E10: =IF(D10="y",$H$113,0) | F10: =E10*$C10 | H10: =IF(G10="y",$H$114,0) | I10: =H10*$C10 | K10: =IF(J10="y",$H$115,0) | L10: =K10*$C10 | N10: =IF(M10="y",$H$116,0) | O10: =N10*$C10 | Q10: =IF(P10="y",$H$117,0) | R10: =Q10*$C10 | T10: =IF(S10="y",$H$118,0) | U10: =T10*$C10 | W10: =IF(V10="y",$H$119,0) | X10: =W10*$C10 | Z10: =IF(Y10="y",$H$120,0) | AA10: =Z10*$C10 | AC10: =IF(AB10="y",$H$121,0) | AD10: =AC10*$C10 | AF10: =IF(AE10="y",$H$122,0) | AG10: =AF10*$C10 | AH10: =SUM(F10+I10+L10+O10+R10+U10+X10+AA10+AD10+AG10)
B11: Glass 2.0 system | C11: 121 | E11: =IF(D11="y",$H$113,0) | F11: =E11*$C11 | H11: =IF(G11="y",$H$114,0) | I11: =H11*$C11 | K11: =IF(J11="y",$H$115,0) | L11: =K11*$C11 | N11: =IF(M11="y",$H$116,0) | O11: =N11*$C11 | Q11: =IF(P11="y",$H$117,0) | R11: =Q11*$C11 | T11: =IF(S11="y",$H$118,0) | U11: =T11*$C11 | W11: =IF(V11="y",$H$119,0) | X11: =W11*$C11 | Z11: =IF(Y11="y",$H$120,0) | AA11: =Z11*$C11 | AC11: =IF(AB11="y",$H$121,0) | AD11: =AC11*$C11 | AF11: =IF(AE11="y",$H$122,0) | AG11: =AF11*$C11 | AH11: =SUM(F11+I11+L11+O11+R11+U11+X11+AA11+AD11+AG11)
B12: Stair treads - post lamination polish | C12: 99 | E12: =IF(D12="y",$H$113,0) | F12: =E12*$C12 | H12: =IF(G12="y",$H$114,0) | I12: =H12*$C12 | K12: =IF(J12="y",$H$115,0) | L12: =K12*$C12 | N12: =IF(M12="y",$H$116,0) | O12: =N12*$C12 | Q12: =IF(P12="y",$H$117,0) | R12: =Q12*$C12 | T12: =IF(S12="y",$H$118,0) | U12: =T12*$C12 | W12: =IF(V12="y",$H$119,0) | X12: =W12*$C12 | Z12: =IF(Y12="y",$H$120,0) | AA12: =Z12*$C12 | AC12: =IF(AB12="y",$H$121,0) | AD12: =AC12*$C12 | AF12: =IF(AE12="y",$H$122,0) | AG12: =AF12*$C12 | AH12: =SUM(F12+I12+L12+O12+R12+U12+X12+AA12+AD12+AG12)
B13: Non-Walkable glass | C13: 71 | E13: =IF(D13="y",$H$113,0) | F13: =E13*$C13 | H13: =IF(G13="y",$H$114,0) | I13: =H13*$C13 | K13: =IF(J13="y",$H$115,0) | L13: =K13*$C13 | N13: =IF(M13="y",$H$116,0) | O13: =N13*$C13 | Q13: =IF(P13="y",$H$117,0) | R13: =Q13*$C13 | T13: =IF(S13="y",$H$118,0) | U13: =T13*$C13 | W13: =IF(V13="y",$H$119,0) | X13: =W13*$C13 | Z13: =IF(Y13="y",$H$120,0) | AA13: =Z13*$C13 | AC13: =IF(AB13="y",$H$121,0) | AD13: =AC13*$C13 | AF13: =IF(AE13="y",$H$122,0) | AG13: =AF13*$C13 | AH13: =SUM(F13+I13+L13+O13+R13+U13+X13+AA13+AD13+AG13)
B14: EGR | C14: 95 | E14: =IF(D14="y",$H$113,0) | F14: =E14*$C14 | H14: =IF(G14="y",$H$114,0) | I14: =H14*$C14 | K14: =IF(J14="y",$H$115,0) | L14: =K14*$C14 | N14: =IF(M14="y",$H$116,0) | O14: =N14*$C14 | Q14: =IF(P14="y",$H$117,0) | R14: =Q14*$C14 | T14: =IF(S14="y",$H$118,0) | U14: =T14*$C14 | W14: =IF(V14="y",$H$119,0) | X14: =W14*$C14 | Z14: =IF(Y14="y",$H$120,0) | AA14: =Z14*$C14 | AC14: =IF(AB14="y",$H$121,0) | AD14: =AC14*$C14 | AF14: =IF(AE14="y",$H$122,0) | AG14: =AF14*$C14 | AH14: =SUM(F14+I14+L14+O14+R14+U14+X14+AA14+AD14+AG14)
B15: Options
B16: Sentry Glass interlayer | C16: 4 | E16: =IF(D16="y",$H$113,0) | F16: =E16*$C16 | H16: =IF(G16="y",$H$114,0) | I16: =H16*$C16 | K16: =IF(J16="y",$H$115,0) | L16: =K16*$C16 | N16: =IF(M16="y",$H$116,0) | O16: =N16*$C16 | Q16: =IF(P16="y",$H$117,0) | R16: =Q16*$C16 | T16: =IF(S16="y",$H$118,0) | U16: =T16*$C16 | W16: =IF(V16="y",$H$119,0) | X16: =W16*$C16 | Z16: =IF(Y16="y",$H$120,0) | AA16: =Z16*$C16 | AC16: =IF(AB16="y",$H$121,0) | AD16: =AC16*$C16 | AF16: =IF(AE16="y",$H$122,0) | AG16: =AF16*$C16 | AH16: =SUM(F16+I16+L16+O16+R16+U16+X16+AA16+AD16+AG16)
B17: Colored interlayer | C17: 10 | E17: =IF(D17="y",$H$113,0) | F17: =E17*$C17 | H17: =IF(G17="y",$H$114,0) | I17: =H17*$C17 | K17: =IF(J17="y",$H$115,0) | L17: =K17*$C17 | N17: =IF(M17="y",$H$116,0) | O17: =N17*$C17 | Q17: =IF(P17="y",$H$117,0) | R17: =Q17*$C17 | T17: =IF(S17="y",$H$118,0) | U17: =T17*$C17 | W17: =IF(V17="y",$H$119,0) | X17: =W17*$C17 | Z17: =IF(Y17="y",$H$120,0) | AA17: =Z17*$C17 | AC17: =IF(AB17="y",$H$121,0) | AD17: =AC17*$C17 | AF17: =IF(AE17="y",$H$122,0) | AG17: =AF17*$C17 | AH17: =SUM(F17+I17+L17+O17+R17+U17+X17+AA17+AD17+AG17)
B18: Switchable Glass | C18: 25 | E18: =IF(D18="y",$H$113,0) | F18: =E18*$C18 | H18: =IF(G18="y",$H$114,0) | I18: =H18*$C18 | K18: =IF(J18="y",$H$115,0) | L18: =K18*$C18 | N18: =IF(M18="y",$H$116,0) | O18: =N18*$C18 | Q18: =IF(P18="y",$H$117,0) | R18: =Q18*$C18 | T18: =IF(S18="y",$H$118,0) | U18: =T18*$C18 | W18: =IF(V18="y",$H$119,0) | X18: =W18*$C18 | Z18: =IF(Y18="y",$H$120,0) | AA18: =Z18*$C18 | AC18: =IF(AB18="y",$H$121,0) | AD18: =AC18*$C18 | AF18: =IF(AE18="y",$H$122,0) | AG18: =AF18*$C18 | AH18: =SUM(F18+I18+L18+O18+R18+U18+X18+AA18+AD18+AG18)
B19: Backpaint - Add for all expedited orders | C19: 7.5 | E19: =IF(D19="y",E64+E65,0) | F19: =E19*$C19 | H19: =IF(G19="y",H64+H65,0) | I19: =H19*$C19 | K19: =IF(J19="y",K64+K65,0) | L19: =K19*$C19 | N19: =IF(M19="y",N64+N65,0) | O19: =N19*$C19 | Q19: =IF(P19="y",Q64+Q65,0) | R19: =Q19*$C19 | T19: =IF(S19="y",T64+T65,0) | U19: =T19*$C19 | W19: =IF(V19="y",W64+W65,0) | X19: =W19*$C19 | Z19: =IF(Y19="y",Z64+Z65,0) | AA19: =Z19*$C19 | AC19: =IF(AB19="y",AC64+AC65,0) | AD19: =AC19*$C19 | AF19: =IF(AE19="y",AF64+AF65,0) | AG19: =AF19*$C19 | AH19: =SUM(F19+I19+L19+O19+R19+U19+X19+AA19+AD19+AG19)
B20: Custom | C20: 20 | E20: =IF(D20="y",$H$113,0) | F20: =E20*$C20 | H20: =IF(G20="y",$H$114,0) | I20: =H20*$C20 | K20: =IF(J20="y",$H$115,0) | L20: =K20*$C20 | N20: =IF(M20="y",$H$116,0) | O20: =N20*$C20 | Q20: =IF(P20="y",$H$117,0) | R20: =Q20*$C20 | T20: =IF(S20="y",$H$118,0) | U20: =T20*$C20 | W20: =IF(V20="y",$H$119,0) | X20: =W20*$C20 | Z20: =IF(Y20="y",$H$120,0) | AA20: =Z20*$C20 | AC20: =IF(AB20="y",$H$121,0) | AD20: =AC20*$C20 | AF20: =IF(AE20="y",$H$122,0) | AG20: =AF20*$C20 | AH20: =SUM(F20+I20+L20+O20+R20+U20+X20+AA20+AD20+AG20)
B21: Embeds - Titanium | C21: =40+20 | F21: =E21*$C21 | I21: =H21*$C21 | L21: =K21*$C21 | O21: =N21*$C21 | R21: =Q21*$C21 | U21: =T21*$C21 | X21: =W21*$C21 | AA21: =Z21*$C21 | AD21: =AC21*$C21 | AG21: =AF21*$C21 | AH21: =SUM(F21+I21+L21+O21+R21+U21+X21+AA21+AD21+AG21)
B22: Mounting holes (per hole cost) | C22: 6 | F22: =E22*$C22 | I22: =H22*$C22 | L22: =K22*$C22 | O22: =N22*$C22 | R22: =Q22*$C22 | U22: =T22*$C22 | X22: =W22*$C22 | AA22: =Z22*$C22 | AD22: =AC22*$C22 | AG22: =AF22*$C22 | AH22: =SUM(F22+I22+L22+O22+R22+U22+X22+AA22+AD22+AG22)
B23: Custom shapes | C23: 0.4 | F23: =E23*$C23 | I23: =H23*$C23 | L23: =K23*$C23 | O23: =N23*$C23 | R23: =Q23*$C23 | U23: =T23*$C23 | X23: =W23*$C23 | AA23: =Z23*$C23 | AH23: =SUM(F23+I23+L23+O23+R23+U23+X23+AA23+AD23+AG23)
B24: Round Glass | C24: 0.2 | F24: =IF(D24="Y",F9*$C$24,"") | I24: =IF(G24="Y",I9*$C$24,"") | L24: =IF(J24="Y",L9*$C$24,"") | O24: =IF(M24="Y",O9*$C$24,"") | R24: =IF(P24="Y",R9*$C$24,"") | U24: =IF(S24="Y",U9*$C$24,"") | X24: =IF(V24="Y",X9*$C$24,"") | AA24: =IF(Y24="Y",AA9*$C$24,"") | AH24: =SUM(F24+I24+L24+O24+R24+U24+X24+AA24+AD24+AG24)
B25: Misc Hardware | AH25: =SUM(F25+I25+L25+O25+R25+U25+X25+AA25+AD25+AG25)
B26: Railings
B27: How many sides need railings
C28: Width (Short Side) | F28: Width (Short Side) | I28: Width (Short Side) | L28: Width (Short Side) | O28: Width (Short Side) | R28: Width (Short Side) | U28: Width (Short Side) | X28: Width (Short Side) | AA28: Width (Short Side) | AD28: Width (Short Side) | AG28: Width (Short Side)
C29: Length (Long Side) | F29: Length (Long Side) | I29: Length (Long Side) | L29: Length (Long Side) | O29: Length (Long Side) | R29: Length (Long Side) | U29: Length (Long Side) | X29: Length (Long Side) | AA29: Length (Long Side) | AD29: Length (Long Side) | AG29: Length (Long Side)
B30: Mounting bracket for post | C30: 150 | E30: =IF(AND($D$28=0,$D$29=1),($K113+2),IF(AND($D$28=0,$D$29=2),(($K113*2)+4),IF(AND($D$28=1,$D$29=0),($L113+2),IF(AND($D$28=1,$D$29=1),($K113+$L113+3),IF(AND($D$28=1,$D$29=2),(($K113*2)+4+$L113),IF(AND($D$28=2,$D$29=0),(($L113*2)+4),IF(AND($D$28=2,$D$29=1),($K113+($L113*2)+4),IF(AND($D$28=2,$D$29=2),(($K113*2)+($L113*2)+4),"No Railings")))))))) | F30: =IF(D30="Y",$C$30*E30,"") | H30: =IF(AND($G$28=0,$G$29=1),($K114+2),IF(AND($G$28=0,$G$29=2),(($K114*2)+4),IF(AND($G$28=1,$G$29=0),($L114+2),IF(AND($G$28=1,$G$29=1),($K114+$L114+3),IF(AND($G$28=1,$G$29=2),(($K114*2)+4+$L114),IF(AND($G$28=2,$G$29=0),(($L114*2)+4),IF(AND($G$28=2,$G$29=1),($K114+($L114*2)+4),IF(AND($G$28=2,$G$29=2),(($K114*2)+($L114*2)+4),"No Railings")))))))) | I30: =IF(G30="Y",$C$30*H30,"") | K30: =IF(AND(J28=0,J29=1),($K115+2),IF(AND(J28=1,J29=0),($L115+2),IF(AND(J28=0,J29=2),(($K115*2)+4),IF(AND(J28=1,J29=0),($L115+2),IF(AND(J28=1,J29=1),($K115+2+$L115+1),IF(AND(J28=1,J29=2),(($K115*2)+4+$L115),IF(AND(J28=2,J29=0),(($L115*2)+4),IF(AND(J28=2,J29=1),($K115+2+($L115*2)+2),IF(AND(J28=2,J29=2),(($K115*2)+($L115*2)+4),"No Railings"))))))))) | L30: =IF(J30="Y",$C$30*K30,"") | N30: =IF(AND(M28=0,M29=1),($K116+2),IF(AND(M28=1,M29=0),($L116+2),IF(AND(M28=0,M29=2),(($K116*2)+4),IF(AND(M28=1,M29=0),($L116+2),IF(AND(M28=1,M29=1),($K116+2+$L116+1),IF(AND(M28=1,M29=2),(($K116*2)+4+$L116),IF(AND(M28=2,M29=0),(($L116*2)+4),IF(AND(M28=2,M29=1),($K116+2+($L116*2)+2),IF(AND(M28=2,M29=2),(($K116*2)+($L116*2)+4),"No Railings"))))))))) | O30: =IF(M30="Y",$C$30*N30,"") | Q30: =IF(AND(P28=0,P29=1),($K117+2),IF(AND(P28=1,P29=0),($L117+2),IF(AND(P28=0,P29=2),(($K117*2)+4),IF(AND(P28=1,P29=0),($L117+2),IF(AND(P28=1,P29=1),($K117+2+$L117+1),IF(AND(P28=1,P29=2),(($K117*2)+4+$L117),IF(AND(P28=2,P29=0),(($L117*2)+4),IF(AND(P28=2,P29=1),($K117+2+($L117*2)+2),IF(AND(P28=2,P29=2),(($K117*2)+($L117*2)+4),"No Railings"))))))))) | R30: =IF(P30="Y",$C$30*Q30,"") | T30: =IF(AND(S28=0,S29=1),($K118+2),IF(AND(S28=1,S29=0),($L118+2),IF(AND(S28=0,S29=2),(($K118*2)+4),IF(AND(S28=1,S29=0),($L118+2),IF(AND(S28=1,S29=1),($K118+2+$L118+1),IF(AND(S28=1,S29=2),(($K118*2)+4+$L118),IF(AND(S28=2,S29=0),(($L118*2)+4),IF(AND(S28=2,S29=1),($K118+2+($L118*2)+2),IF(AND(S28=2,S29=2),(($K118*2)+($L118*2)+4),"No Railings"))))))))) | U30: =IF(S30="Y",$C$30*T30,"") | W30: =IF(AND(V28=0,V29=1),($K119+2),IF(AND(V28=1,V29=0),($L119+2),IF(AND(V28=0,V29=2),(($K119*2)+4),IF(AND(V28=1,V29=0),($L119+2),IF(AND(V28=1,V29=1),($K119+2+$L119+1),IF(AND(V28=1,V29=2),(($K119*2)+4+$L119),IF(AND(V28=2,V29=0),(($L119*2)+4),IF(AND(V28=2,V29=1),($K119+2+($L119*2)+2),IF(AND(V28=2,V29=2),(($K119*2)+($L119*2)+4),"No Railings"))))))))) | X30: =IF(V30="Y",$C$30*W30,"") | Z30: =IF(AND(Y28=0,Y29=1),($K120+2),IF(AND(Y28=1,Y29=0),($L120+2),IF(AND(Y28=0,Y29=2),(($K120*2)+4),IF(AND(Y28=1,Y29=0),($L120+2),IF(AND(Y28=1,Y29=1),($K120+2+$L120+1),IF(AND(Y28=1,Y29=2),(($K120*2)+4+$L120),IF(AND(Y28=2,Y29=0),(($L120*2)+4),IF(AND(Y28=2,Y29=1),($K120+2+($L120*2)+2),IF(AND(Y28=2,Y29=2),(($K120*2)+($L120*2)+4),"No Railings"))))))))) | AA30: =IF(Y30="Y",$C$30*Z30,"") | AC30: =IF(AND(AB28=0,AB29=1),($K121+2),IF(AND(AB28=1,AB29=0),($L121+2),IF(AND(AB28=0,AB29=2),(($K121*2)+4),IF(AND(AB28=1,AB29=0),($L121+2),IF(AND(AB28=1,AB29=1),($K121+2+$L121+1),IF(AND(AB28=1,AB29=2),(($K121*2)+4+$L121),IF(AND(AB28=2,AB29=0),(($L121*2)+4),IF(AND(AB28=2,AB29=1),($K121+2+($L121*2)+2),IF(AND(AB28=2,AB29=2),(($K121*2)+($L121*2)+4),"No Railings"))))))))) | AD30: =IF(AB30="Y",$C$30*AC30,"") | AF30: =IF(AND(AE28=0,AE29=1),($K122+2),IF(AND(AE28=1,AE29=0),($L122+2),IF(AND(AE28=0,AE29=2),(($K122*2)+4),IF(AND(AE28=1,AE29=0),($L122+2),IF(AND(AE28=1,AE29=1),($K122+2+$L122+1),IF(AND(AE28=1,AE29=2),(($K122*2)+4+$L122),IF(AND(AE28=2,AE29=0),(($L122*2)+4),IF(AND(AE28=2,AE29=1),($K122+2+($L122*2)+2),IF(AND(AE28=2,AE29=2),(($K122*2)+($L122*2)+4),"No Railings"))))))))) | AG30: =IF(AE30="Y",$C$30*AF30,"") | AH30: =SUM(F30+I30+L30+O30+R30+U30+X30+AA30+AD30+AG30)
B31: Uprights | C31: 200 | E31: =IF(AND($D$28=0,$D$29=1),($K113+2),IF(AND($D$28=0,$D$29=2),(($K113*2)+4),IF(AND($D$28=1,$D$29=0),($L113+2),IF(AND($D$28=1,$D$29=1),($K113+$L113+3),IF(AND($D$28=1,$D$29=2),(($K113*2)+4+$L113),IF(AND($D$28=2,$D$29=0),(($L113*2)+4),IF(AND($D$28=2,$D$29=1),($K113+($L113*2)+4),IF(AND($D$28=2,$D$29=2),(($K113*2)+($L113*2)+4),"No Railings")))))))) | F31: =IF(D31="Y",$C$31*E31,"") | H31: =IF(AND(G28=0,G29=1),($K114+2),IF(AND(G28=1,G29=0),($L114+2),IF(AND(G28=0,G29=2),(($K114*2)+4),IF(AND(G28=1,G29=0),($L114+2),IF(AND(G28=1,G29=1),($K114+2+$L114+1),IF(AND(G28=1,G29=2),(($K114*2)+4+$L114),IF(AND(G28=2,G29=0),(($L114*2)+4),IF(AND(G28=2,G29=1),($K114+2+($L114*2)+2),IF(AND(G28=2,G29=2),(($K114*2)+($L114*2)+4),"No Railings"))))))))) | I31: =IF(G31="Y",$C$31*H31,"") | K31: =IF(AND(J28=0,J29=1),($K115+2),IF(AND(J28=1,J29=0),($L115+2),IF(AND(J28=0,J29=2),(($K115*2)+4),IF(AND(J28=1,J29=0),($L115+2),IF(AND(J28=1,J29=1),($K115+2+$L115+1),IF(AND(J28=1,J29=2),(($K115*2)+4+$L115),IF(AND(J28=2,J29=0),(($L115*2)+4),IF(AND(J28=2,J29=1),($K115+2+($L115*2)+2),IF(AND(J28=2,J29=2),(($K115*2)+($L115*2)+4),"No Railings"))))))))) | L31: =IF(J31="Y",$C$31*K31,"") | N31: =IF(AND(M28=0,M29=1),($K116+2),IF(AND(M28=1,M29=0),($L116+2),IF(AND(M28=0,M29=2),(($K116*2)+4),IF(AND(M28=1,M29=0),($L116+2),IF(AND(M28=1,M29=1),($K116+2+$L116+1),IF(AND(M28=1,M29=2),(($K116*2)+4+$L116),IF(AND(M28=2,M29=0),(($L116*2)+4),IF(AND(M28=2,M29=1),($K116+2+($L116*2)+2),IF(AND(M28=2,M29=2),(($K116*2)+($L116*2)+4),"No Railings"))))))))) | O31: =IF(M31="Y",$C$31*N31,"") | Q31: =IF(AND(P28=0,P29=1),($K117+2),IF(AND(P28=1,P29=0),($L117+2),IF(AND(P28=0,P29=2),(($K117*2)+4),IF(AND(P28=1,P29=0),($L117+2),IF(AND(P28=1,P29=1),($K117+2+$L117+1),IF(AND(P28=1,P29=2),(($K117*2)+4+$L117),IF(AND(P28=2,P29=0),(($L117*2)+4),IF(AND(P28=2,P29=1),($K117+2+($L117*2)+2),IF(AND(P28=2,P29=2),(($K117*2)+($L117*2)+4),"No Railings"))))))))) | R31: =IF(P31="Y",$C$31*Q31,"") | T31: =IF(AND(S28=0,S29=1),($K118+2),IF(AND(S28=1,S29=0),($L118+2),IF(AND(S28=0,S29=2),(($K118*2)+4),IF(AND(S28=1,S29=0),($L118+2),IF(AND(S28=1,S29=1),($K118+2+$L118+1),IF(AND(S28=1,S29=2),(($K118*2)+4+$L118),IF(AND(S28=2,S29=0),(($L118*2)+4),IF(AND(S28=2,S29=1),($K118+2+($L118*2)+2),IF(AND(S28=2,S29=2),(($K118*2)+($L118*2)+4),"No Railings"))))))))) | U31: =IF(S31="Y",$C$31*T31,"") | W31: =IF(AND(V28=0,V29=1),($K119+2),IF(AND(V28=1,V29=0),($L119+2),IF(AND(V28=0,V29=2),(($K119*2)+4),IF(AND(V28=1,V29=0),($L119+2),IF(AND(V28=1,V29=1),($K119+2+$L119+1),IF(AND(V28=1,V29=2),(($K119*2)+4+$L119),IF(AND(V28=2,V29=0),(($L119*2)+4),IF(AND(V28=2,V29=1),($K119+2+($L119*2)+2),IF(AND(V28=2,V29=2),(($K119*2)+($L119*2)+4),"No Railings"))))))))) | X31: =IF(V31="Y",$C$31*W31,"") | Z31: =IF(AND(Y28=0,Y29=1),($K120+2),IF(AND(Y28=1,Y29=0),($L120+2),IF(AND(Y28=0,Y29=2),(($K120*2)+4),IF(AND(Y28=1,Y29=0),($L120+2),IF(AND(Y28=1,Y29=1),($K120+2+$L120+1),IF(AND(Y28=1,Y29=2),(($K120*2)+4+$L120),IF(AND(Y28=2,Y29=0),(($L120*2)+4),IF(AND(Y28=2,Y29=1),($K120+2+($L120*2)+2),IF(AND(Y28=2,Y29=2),(($K120*2)+($L120*2)+4),"No Railings"))))))))) | AA31: =IF(Y31="Y",$C$31*Z31,"") | AC31: =IF(AND(AB28=0,AB29=1),($K121+2),IF(AND(AB28=1,AB29=0),($L121+2),IF(AND(AB28=0,AB29=2),(($K121*2)+4),IF(AND(AB28=1,AB29=0),($L121+2),IF(AND(AB28=1,AB29=1),($K121+2+$L121+1),IF(AND(AB28=1,AB29=2),(($K121*2)+4+$L121),IF(AND(AB28=2,AB29=0),(($L121*2)+4),IF(AND(AB28=2,AB29=1),($K121+2+($L121*2)+2),IF(AND(AB28=2,AB29=2),(($K121*2)+($L121*2)+4),"No Railings"))))))))) | AD31: =IF(AB31="Y",$C$31*AC31,"") | AF31: =IF(AND(AE28=0,AE29=1),($K122+2),IF(AND(AE28=1,AE29=0),($L122+2),IF(AND(AE28=0,AE29=2),(($K122*2)+4),IF(AND(AE28=1,AE29=0),($L122+2),IF(AND(AE28=1,AE29=1),($K122+2+$L122+1),IF(AND(AE28=1,AE29=2),(($K122*2)+4+$L122),IF(AND(AE28=2,AE29=0),(($L122*2)+4),IF(AND(AE28=2,AE29=1),($K122+2+($L122*2)+2),IF(AND(AE28=2,AE29=2),(($K122*2)+($L122*2)+4),"No Railings"))))))))) | AG31: =IF(AE31="Y",$C$31*AF31,"") | AH31: =SUM(F31+I31+L31+O31+R31+U31+X31+AA31+AD31+AG31)
B32: Cable Railing - per linear foot | C32: 55 | E32: =IF(AND($D$28=0,$D$29=1),($F$113/12),IF(AND($D$28=0,$D$29=2),(($F$113*2)/12),IF(AND($D$28=1,$D$29=0),($E$113/12),IF(AND($D$28=1,$D$29=1),(($E$113+$F$113)/12),IF(AND($D$28=1,$D$29=2),(($E$113+($F$113*2))/12),IF(AND($D$28=2,$D$29=0),(($E$113*2)/12),IF(AND($D$28=2,$D$29=1),((($E$113*2)+$F$113)/12),IF(AND($D$28=2,$D$29=2),((($E$113*2)+($F$113*2))/12),"No Railings")))))))) | F32: =IF(D32="Y",$C$32*E32,"") | H32: =IF(AND($G$28=0,$G$29=1),($F$114/12),IF(AND($G$28=0,$G$29=2),(($F$114*2)/12),IF(AND($G$28=1,$G$29=0),($E$114/12),IF(AND($G$28=1,$G$29=1),(($E$114+$F$114)/12),IF(AND($G$28=1,$G$29=2),(($E$114+($F$114*2))/12),IF(AND($G$28=2,$G$29=0),(($E$114*2)/12),IF(AND($G$28=2,$G$29=1),((($E$114*2)+$F$114)/12),IF(AND($G$28=2,$G$29=2),((($E$114*2)+($F$114*2))/12),"No Railings")))))))) | I32: =IF(G32="Y",$C$32*H32,"") | K32: =IF(AND($J$28=0,$J$29=1),($F$115/12),IF(AND($J$28=0,$J$29=2),(($F$115*2)/12),IF(AND($J$28=1,$J$29=0),($E$115/12),IF(AND($J$28=1,$J$29=1),(($E$115+$F$115)/12),IF(AND($J$28=1,$J$29=2),(($E$115+($F$115*2))/12),IF(AND($J$28=2,$J$29=0),(($E$115*2)/12),IF(AND($J$28=2,$J$29=1),((($E$115*2)+$F$115)/12),IF(AND($J$28=2,$J$29=2),((($E$115*2)+($F$115*2))/12),"No Railings")))))))) | L32: =IF(J32="Y",$C$32*K32,"") | N32: =IF(AND($M$28=0,$M$29=1),($F$116/12),IF(AND($M$28=0,$M$29=2),(($F$116*2)/12),IF(AND($M$28=1,$M$29=0),($E$116/12),IF(AND($M$28=1,$M$29=1),(($E$116+$F$116)/12),IF(AND($M$28=1,$M$29=2),(($E$116+($F$116*2))/12),IF(AND($M$28=2,$M$29=0),(($E$116*2)/12),IF(AND($M$28=2,$M$29=1),((($E$116*2)+$F$116)/12),IF(AND($M$28=2,$M$29=2),((($E$116*2)+($F$116*2))/12),"No Railings")))))))) | O32: =IF(M32="Y",$C$32*N32,"") | Q32: =IF(AND($P$28=0,$P$29=1),($F$117/12),IF(AND($P$28=0,$P$29=2),(($F$117*2)/12),IF(AND($P$28=1,$P$29=0),($E$117/12),IF(AND($P$28=1,$P$29=1),(($E$117+$F$117)/12),IF(AND($P$28=1,$P$29=2),(($E$117+($F$117*2))/12),IF(AND($P$28=2,$P$29=0),(($E$117*2)/12),IF(AND($P$28=2,$P$29=1),((($E$117*2)+$F$117)/12),IF(AND($P$28=2,$P$29=2),((($E$117*2)+($F$117*2))/12),"No Railings")))))))) | R32: =IF(P32="Y",$C$32*Q32,"") | T32: =IF(AND($S$28=0,$S$29=1),($F$118/12),IF(AND($S$28=0,$S$29=2),(($F$118*2)/12),IF(AND($S$28=1,$S$29=0),($E$118/12),IF(AND($S$28=1,$S$29=1),(($E$118+$F$118)/12),IF(AND($S$28=1,$S$29=2),(($E$118+($F$118*2))/12),IF(AND($S$28=2,$S$29=0),(($E$118*2)/12),IF(AND($S$28=2,$S$29=1),((($E$118*2)+$F$118)/12),IF(AND($S$28=2,$S$29=2),((($E$118*2)+($F$118*2))/12),"No Railings")))))))) | U32: =IF(S32="Y",$C$32*T32,"") | W32: =IF(AND($V$28=0,$V$29=1),($F$119/12),IF(AND($V$28=0,$V$29=2),(($F$119*2)/12),IF(AND($V$28=1,$V$29=0),($E$119/12),IF(AND($V$28=1,$V$29=1),(($E$119+$F$119)/12),IF(AND($V$28=1,$V$29=2),(($E$119+($F$119*2))/12),IF(AND($V$28=2,$V$29=0),(($E$119*2)/12),IF(AND($V$28=2,$V$29=1),((($E$119*2)+$F$119)/12),IF(AND($V$28=2,$V$29=2),((($E$119*2)+($F$119*2))/12),"No Railings")))))))) | X32: =IF(V32="Y",$C$32*W32,"") | Z32: =IF(AND($Y$28=0,$Y$29=1),($F$120/12),IF(AND($Y$28=0,$Y$29=2),(($F$120*2)/12),IF(AND($Y$28=1,$Y$29=0),($E$120/12),IF(AND($Y$28=1,$Y$29=1),(($E$120+$F$120)/12),IF(AND($Y$28=1,$Y$29=2),(($E$120+($F$120*2))/12),IF(AND($Y$28=2,$Y$29=0),(($E$120*2)/12),IF(AND($Y$28=2,$Y$29=1),((($E$120*2)+$F$120)/12),IF(AND($Y$28=2,$Y$29=2),((($E$120*2)+($F$120*2))/12),"No Railings")))))))) | AA32: =IF(Y32="Y",$C$32*Z32,"") | AC32: =IF(AND($AB$28=0,$AB$29=1),($F$121/12),IF(AND($AB$28=0,$AB$29=2),(($F$121*2)/12),IF(AND($AB$28=1,$AB$29=0),($E$121/12),IF(AND($AB$28=1,$AB$29=1),(($E$121+$F$121)/12),IF(AND($AB$28=1,$AB$29=2),(($E$121+($F$121*2))/12),IF(AND($AB$28=2,$AB$29=0),(($E$121*2)/12),IF(AND($AB$28=2,$AB$29=1),((($E$121*2)+$F$121)/12),IF(AND($AB$28=2,$AB$29=2),((($E$121*2)+($F$121*2))/12),"No Railings")))))))) | AD32: =IF(AB32="Y",$C$32*AC32,"") | AF32: =IF(AND($AE$28=0,$AE$29=1),($F$122/12),IF(AND($AE$28=0,$AE$29=2),(($F$122*2)/12),IF(AND($AE$28=1,$AE$29=0),($E$122/12),IF(AND($AE$28=1,$AE$29=1),(($E$122+$F$122)/12),IF(AND($AE$28=1,$AE$29=2),(($E$122+($F$122*2))/12),IF(AND($AE$28=2,$AE$29=0),(($E$122*2)/12),IF(AND($AE$28=2,$AE$29=1),((($E$122*2)+$F$122)/12),IF(AND($AE$28=2,$AE$29=2),((($E$122*2)+($F$122*2))/12),"No Railings")))))))) | AG32: =IF(AE32="Y",$C$32*AF32,"") | AH32: =SUM(F32+I32+L32+O32+R32+U32+X32+AA32+AD32+AG32)
B33: Glass Railing - 42" High - per linear foot | C33: 91 | E33: =IF(AND($D$28=0,$D$29=1),($F$113/12),IF(AND($D$28=0,$D$29=2),(($F$113*2)/12),IF(AND($D$28=1,$D$29=0),($E$113/12),IF(AND($D$28=1,$D$29=1),(($E$113+$F$113)/12),IF(AND($D$28=1,$D$29=2),(($E$113+($F$113*2))/12),IF(AND($D$28=2,$D$29=0),(($E$113*2)/12),IF(AND($D$28=2,$D$29=1),((($E$113*2)+$F$113)/12),IF(AND($D$28=2,$D$29=2),((($E$113*2)+($F$113*2))/12),"No Railings")))))))) | F33: =IF(D33="Y",$C$33*E33,"") | H33: =IF(AND($G$28=0,$G$29=1),($F$114/12),IF(AND($G$28=0,$G$29=2),(($F$114*2)/12),IF(AND($G$28=1,$G$29=0),($E$114/12),IF(AND($G$28=1,$G$29=1),(($E$114+$F$114)/12),IF(AND($G$28=1,$G$29=2),(($E$114+($F$114*2))/12),IF(AND($G$28=2,$G$29=0),(($E$114*2)/12),IF(AND($G$28=2,$G$29=1),((($E$114*2)+$F$114)/12),IF(AND($G$28=2,$G$29=2),((($E$114*2)+($F$114*2))/12),"No Railings")))))))) | I33: =IF(G33="Y",$C$33*H33,"") | K33: =IF(AND($J$28=0,$J$29=1),($F$115/12),IF(AND($J$28=0,$J$29=2),(($F$115*2)/12),IF(AND($J$28=1,$J$29=0),($E$115/12),IF(AND($J$28=1,$J$29=1),(($E$115+$F$115)/12),IF(AND($J$28=1,$J$29=2),(($E$115+($F$115*2))/12),IF(AND($J$28=2,$J$29=0),(($E$115*2)/12),IF(AND($J$28=2,$J$29=1),((($E$115*2)+$F$115)/12),IF(AND($J$28=2,$J$29=2),((($E$115*2)+($F$115*2))/12),"No Railings")))))))) | L33: =IF(J33="Y",$C$33*K33,"") | N33: =IF(AND($M$28=0,$M$29=1),($F$116/12),IF(AND($M$28=0,$M$29=2),(($F$116*2)/12),IF(AND($M$28=1,$M$29=0),($E$116/12),IF(AND($M$28=1,$M$29=1),(($E$116+$F$116)/12),IF(AND($M$28=1,$M$29=2),(($E$116+($F$116*2))/12),IF(AND($M$28=2,$M$29=0),(($E$116*2)/12),IF(AND($M$28=2,$M$29=1),((($E$116*2)+$F$116)/12),IF(AND($M$28=2,$M$29=2),((($E$116*2)+($F$116*2))/12),"No Railings")))))))) | O33: =IF(M33="Y",$C$33*N33,"") | Q33: =IF(AND($P$28=0,$P$29=1),($F$117/12),IF(AND($P$28=0,$P$29=2),(($F$117*2)/12),IF(AND($P$28=1,$P$29=0),($E$117/12),IF(AND($P$28=1,$P$29=1),(($E$117+$F$117)/12),IF(AND($P$28=1,$P$29=2),(($E$117+($F$117*2))/12),IF(AND($P$28=2,$P$29=0),(($E$117*2)/12),IF(AND($P$28=2,$P$29=1),((($E$117*2)+$F$117)/12),IF(AND($P$28=2,$P$29=2),((($E$117*2)+($F$117*2))/12),"No Railings")))))))) | R33: =IF(P33="Y",$C$33*Q33,"") | T33: =IF(AND($S$28=0,$S$29=1),($F$118/12),IF(AND($S$28=0,$S$29=2),(($F$118*2)/12),IF(AND($S$28=1,$S$29=0),($E$118/12),IF(AND($S$28=1,$S$29=1),(($E$118+$F$118)/12),IF(AND($S$28=1,$S$29=2),(($E$118+($F$118*2))/12),IF(AND($S$28=2,$S$29=0),(($E$118*2)/12),IF(AND($S$28=2,$S$29=1),((($E$118*2)+$F$118)/12),IF(AND($S$28=2,$S$29=2),((($E$118*2)+($F$118*2))/12),"No Railings")))))))) | U33: =IF(S33="Y",$C$33*T33,"") | W33: =IF(AND($V$28=0,$V$29=1),($F$119/12),IF(AND($V$28=0,$V$29=2),(($F$119*2)/12),IF(AND($V$28=1,$V$29=0),($E$119/12),IF(AND($V$28=1,$V$29=1),(($E$119+$F$119)/12),IF(AND($V$28=1,$V$29=2),(($E$119+($F$119*2))/12),IF(AND($V$28=2,$V$29=0),(($E$119*2)/12),IF(AND($V$28=2,$V$29=1),((($E$119*2)+$F$119)/12),IF(AND($V$28=2,$V$29=2),((($E$119*2)+($F$119*2))/12),"No Railings")))))))) | X33: =IF(V33="Y",$C$33*W33,"") | Z33: =IF(AND($Y$28=0,$Y$29=1),($F$120/12),IF(AND($Y$28=0,$Y$29=2),(($F$120*2)/12),IF(AND($Y$28=1,$Y$29=0),($E$120/12),IF(AND($Y$28=1,$Y$29=1),(($E$120+$F$120)/12),IF(AND($Y$28=1,$Y$29=2),(($E$120+($F$120*2))/12),IF(AND($Y$28=2,$Y$29=0),(($E$120*2)/12),IF(AND($Y$28=2,$Y$29=1),((($E$120*2)+$F$120)/12),IF(AND($Y$28=2,$Y$29=2),((($E$120*2)+($F$120*2))/12),"No Railings")))))))) | AA33: =IF(Y33="Y",$C$33*Z33,"") | AC33: =IF(AND($AB$28=0,$AB$29=1),($F$121/12),IF(AND($AB$28=0,$AB$29=2),(($F$121*2)/12),IF(AND($AB$28=1,$AB$29=0),($E$121/12),IF(AND($AB$28=1,$AB$29=1),(($E$121+$F$121)/12),IF(AND($AB$28=1,$AB$29=2),(($E$121+($F$121*2))/12),IF(AND($AB$28=2,$AB$29=0),(($E$121*2)/12),IF(AND($AB$28=2,$AB$29=1),((($E$121*2)+$F$121)/12),IF(AND($AB$28=2,$AB$29=2),((($E$121*2)+($F$121*2))/12),"No Railings")))))))) | AD33: =IF(AB33="Y",$C$33*AC33,"") | AF33: =IF(AND($AE$28=0,$AE$29=1),($F$122/12),IF(AND($AE$28=0,$AE$29=2),(($F$122*2)/12),IF(AND($AE$28=1,$AE$29=0),($E$122/12),IF(AND($AE$28=1,$AE$29=1),(($E$122+$F$122)/12),IF(AND($AE$28=1,$AE$29=2),(($E$122+($F$122*2))/12),IF(AND($AE$28=2,$AE$29=0),(($E$122*2)/12),IF(AND($AE$28=2,$AE$29=1),((($E$122*2)+$F$122)/12),IF(AND($AE$28=2,$AE$29=2),((($E$122*2)+($F$122*2))/12),"No Railings")))))))) | AG33: =IF(AE33="Y",$C$33*AF33,"") | AH33: =SUM(F33+I33+L33+O33+R33+U33+X33+AA33+AD33+AG33)
B34: Top Rail - per linear foot | C34: 120 | E34: =IF(AND($D$28=0,$D$29=1),($F$113/12),IF(AND($D$28=0,$D$29=2),(($F$113*2)/12),IF(AND($D$28=1,$D$29=0),($E$113/12),IF(AND($D$28=1,$D$29=1),(($E$113+$F$113)/12),IF(AND($D$28=1,$D$29=2),(($E$113+($F$113*2))/12),IF(AND($D$28=2,$D$29=0),(($E$113*2)/12),IF(AND($D$28=2,$D$29=1),((($E$113*2)+$F$113)/12),IF(AND($D$28=2,$D$29=2),((($E$113*2)+($F$113*2))/12),"No Railings")))))))) | F34: =IF(D34="Y",$C$34*E34,"") | H34: =IF(AND($G$28=0,$G$29=1),($F$114/12),IF(AND($G$28=0,$G$29=2),(($F$114*2)/12),IF(AND($G$28=1,$G$29=0),($E$114/12),IF(AND($G$28=1,$G$29=1),(($E$114+$F$114)/12),IF(AND($G$28=1,$G$29=2),(($E$114+($F$114*2))/12),IF(AND($G$28=2,$G$29=0),(($E$114*2)/12),IF(AND($G$28=2,$G$29=1),((($E$114*2)+$F$114)/12),IF(AND($G$28=2,$G$29=2),((($E$114*2)+($F$114*2))/12),"No Railings")))))))) | I34: =IF(G34="Y",$C$34*H34,"") | K34: =IF(AND($J$28=0,$J$29=1),($F$115/12),IF(AND($J$28=0,$J$29=2),(($F$115*2)/12),IF(AND($J$28=1,$J$29=0),($E$115/12),IF(AND($J$28=1,$J$29=1),(($E$115+$F$115)/12),IF(AND($J$28=1,$J$29=2),(($E$115+($F$115*2))/12),IF(AND($J$28=2,$J$29=0),(($E$115*2)/12),IF(AND($J$28=2,$J$29=1),((($E$115*2)+$F$115)/12),IF(AND($J$28=2,$J$29=2),((($E$115*2)+($F$115*2))/12),"No Railings")))))))) | L34: =IF(J34="Y",$C$34*K34,"") | N34: =IF(AND($M$28=0,$M$29=1),($F$116/12),IF(AND($M$28=0,$M$29=2),(($F$116*2)/12),IF(AND($M$28=1,$M$29=0),($E$116/12),IF(AND($M$28=1,$M$29=1),(($E$116+$F$116)/12),IF(AND($M$28=1,$M$29=2),(($E$116+($F$116*2))/12),IF(AND($M$28=2,$M$29=0),(($E$116*2)/12),IF(AND($M$28=2,$M$29=1),((($E$116*2)+$F$116)/12),IF(AND($M$28=2,$M$29=2),((($E$116*2)+($F$116*2))/12),"No Railings")))))))) | O34: =IF(M34="Y",$C$34*N34,"") | Q34: =IF(AND($P$28=0,$P$29=1),($F$117/12),IF(AND($P$28=0,$P$29=2),(($F$117*2)/12),IF(AND($P$28=1,$P$29=0),($E$117/12),IF(AND($P$28=1,$P$29=1),(($E$117+$F$117)/12),IF(AND($P$28=1,$P$29=2),(($E$117+($F$117*2))/12),IF(AND($P$28=2,$P$29=0),(($E$117*2)/12),IF(AND($P$28=2,$P$29=1),((($E$117*2)+$F$117)/12),IF(AND($P$28=2,$P$29=2),((($E$117*2)+($F$117*2))/12),"No Railings")))))))) | R34: =IF(P34="Y",$C$34*Q34,"") | T34: =IF(AND($S$28=0,$S$29=1),($F$118/12),IF(AND($S$28=0,$S$29=2),(($F$118*2)/12),IF(AND($S$28=1,$S$29=0),($E$118/12),IF(AND($S$28=1,$S$29=1),(($E$118+$F$118)/12),IF(AND($S$28=1,$S$29=2),(($E$118+($F$118*2))/12),IF(AND($S$28=2,$S$29=0),(($E$118*2)/12),IF(AND($S$28=2,$S$29=1),((($E$118*2)+$F$118)/12),IF(AND($S$28=2,$S$29=2),((($E$118*2)+($F$118*2))/12),"No Railings")))))))) | U34: =IF(S34="Y",$C$34*T34,"") | W34: =IF(AND($V$28=0,$V$29=1),($F$119/12),IF(AND($V$28=0,$V$29=2),(($F$119*2)/12),IF(AND($V$28=1,$V$29=0),($E$119/12),IF(AND($V$28=1,$V$29=1),(($E$119+$F$119)/12),IF(AND($V$28=1,$V$29=2),(($E$119+($F$119*2))/12),IF(AND($V$28=2,$V$29=0),(($E$119*2)/12),IF(AND($V$28=2,$V$29=1),((($E$119*2)+$F$119)/12),IF(AND($V$28=2,$V$29=2),((($E$119*2)+($F$119*2))/12),"No Railings")))))))) | X34: =IF(V34="Y",$C$34*W34,"") | Z34: =IF(AND($Y$28=0,$Y$29=1),($F$120/12),IF(AND($Y$28=0,$Y$29=2),(($F$120*2)/12),IF(AND($Y$28=1,$Y$29=0),($E$120/12),IF(AND($Y$28=1,$Y$29=1),(($E$120+$F$120)/12),IF(AND($Y$28=1,$Y$29=2),(($E$120+($F$120*2))/12),IF(AND($Y$28=2,$Y$29=0),(($E$120*2)/12),IF(AND($Y$28=2,$Y$29=1),((($E$120*2)+$F$120)/12),IF(AND($Y$28=2,$Y$29=2),((($E$120*2)+($F$120*2))/12),"No Railings")))))))) | AA34: =IF(Y34="Y",$C$34*Z34,"") | AC34: =IF(AND($AB$28=0,$AB$29=1),($F$121/12),IF(AND($AB$28=0,$AB$29=2),(($F$121*2)/12),IF(AND($AB$28=1,$AB$29=0),($E$121/12),IF(AND($AB$28=1,$AB$29=1),(($E$121+$F$121)/12),IF(AND($AB$28=1,$AB$29=2),(($E$121+($F$121*2))/12),IF(AND($AB$28=2,$AB$29=0),(($E$121*2)/12),IF(AND($AB$28=2,$AB$29=1),((($E$121*2)+$F$121)/12),IF(AND($AB$28=2,$AB$29=2),((($E$121*2)+($F$121*2))/12),"No Railings")))))))) | AD34: =IF(AB34="Y",$C$34*AC34,"") | AF34: =IF(AND($AE$28=0,$AE$29=1),($F$122/12),IF(AND($AE$28=0,$AE$29=2),(($F$122*2)/12),IF(AND($AE$28=1,$AE$29=0),($E$122/12),IF(AND($AE$28=1,$AE$29=1),(($E$122+$F$122)/12),IF(AND($AE$28=1,$AE$29=2),(($E$122+($F$122*2))/12),IF(AND($AE$28=2,$AE$29=0),(($E$122*2)/12),IF(AND($AE$28=2,$AE$29=1),((($E$122*2)+$F$122)/12),IF(AND($AE$28=2,$AE$29=2),((($E$122*2)+($F$122*2))/12),"No Railings")))))))) | AG34: =IF(AE34="Y",$C$34*AF34,"") | AH34: =SUM(F34+I34+L34+O34+R34+U34+X34+AA34+AD34+AG34)
B35: Framing - Linear Feet
B36: Perimeter
B37: Series 1000 Pedestal thermally broken | C37: ='Bonnell - Glass Pricing'!H14 | E37: =IF(D37="y",$I$113,0) | F37: =E37*$C37 | H37: =IF(G37="y",$I$114,0) | I37: =H37*$C37 | K37: =IF(J37="y",$I$115,0) | L37: =K37*$C37 | N37: =IF(M37="y",$I$116,0) | O37: =N37*$C37 | Q37: =IF(P37="y",$I$117,0) | R37: =Q37*$C37 | T37: =IF(S37="y",$I$118,0) | U37: =T37*$C37 | W37: =IF(V37="y",$I$119,0) | X37: =W37*$C37 | Z37: =IF(Y37="y",$I$120,0) | AA37: =Z37*$C37 | AC37: =IF(AB37="y",$I$121,0) | AD37: =AC37*$C37 | AF37: =IF(AE37="y",$I$122,0) | AG37: =AF37*$C37 | AH37: =SUM(F37+I37+L37+O37+R37+U37+X37+AA37+AD37+AG37)
B38: Series 1000 Recessed thermally broken | C38: ='Bonnell - Glass Pricing'!H15 | E38: =IF(D38="y",$I$113,0) | F38: =E38*$C38 | H38: =IF(G38="y",$I$114,0) | I38: =H38*$C38 | K38: =IF(J38="y",$I$115,0) | L38: =K38*$C38 | N38: =IF(M38="y",$I$116,0) | O38: =N38*$C38 | Q38: =IF(P38="y",$I$117,0) | R38: =Q38*$C38 | T38: =IF(S38="y",$I$118,0) | U38: =T38*$C38 | W38: =IF(V38="y",$I$119,0) | X38: =W38*$C38 | Z38: =IF(Y38="y",$I$120,0) | AA38: =Z38*$C38 | AC38: =IF(AB38="y",$I$121,0) | AD38: =AC38*$C38 | AF38: =IF(AE38="y",$I$122,0) | AG38: =AF38*$C38 | AH38: =SUM(F38+I38+L38+O38+R38+U38+X38+AA38+AD38+AG38)
B39: Perimeter non thermally broken | C39: ='Bonnell - Glass Pricing'!H16 | E39: =IF(D39="y",$I$113,0) | F39: =E39*$C39 | H39: =IF(G39="y",$I$114,0) | I39: =H39*$C39 | K39: =IF(J39="y",$I$115,0) | L39: =K39*$C39 | N39: =IF(M39="y",$I$116,0) | O39: =N39*$C39 | Q39: =IF(P39="y",$I$117,0) | R39: =Q39*$C39 | T39: =IF(S39="y",$I$118,0) | U39: =T39*$C39 | W39: =IF(V39="y",$I$119,0) | X39: =W39*$C39 | Z39: =IF(Y39="y",$I$120,0) | AA39: =Z39*$C39 | AC39: =IF(AB39="y",$I$121,0) | AD39: =AC39*$C39 | AF39: =IF(AE39="y",$I$122,0) | AG39: =AF39*$C39 | AH39: =SUM(F39+I39+L39+O39+R39+U39+X39+AA39+AD39+AG39)
B40: Series 2000 Pedestal | C40: ='Bonnell - Glass Pricing'!H46 | E40: =IF(D40="y",$I$113,0) | F40: =E40*$C40 | H40: =IF(G40="y",$I$114,0) | I40: =H40*$C40 | K40: =IF(J40="y",$I$115,0) | L40: =K40*$C40 | N40: =IF(M40="y",$I$116,0) | O40: =N40*$C40 | Q40: =IF(P40="y",$I$117,0) | R40: =Q40*$C40 | T40: =IF(S40="y",$I$118,0) | U40: =T40*$C40 | W40: =IF(V40="y",$I$119,0) | X40: =W40*$C40 | Z40: =IF(Y40="y",$I$120,0) | AA40: =Z40*$C40 | AC40: =IF(AB40="y",$I$121,0) | AD40: =AC40*$C40 | AF40: =IF(AE40="y",$I$122,0) | AG40: =AF40*$C40 | AH40: =SUM(F40+I40+L40+O40+R40+U40+X40+AA40+AD40+AG40)
B41: Series 2000 Recessed | C41: ='Bonnell - Glass Pricing'!H47 | E41: =IF(D41="y",$I$113,0) | F41: =E41*$C41 | H41: =IF(G41="y",$I$114,0) | I41: =H41*$C41 | K41: =IF(J41="y",$I$115,0) | L41: =K41*$C41 | N41: =IF(M41="y",$I$116,0) | O41: =N41*$C41 | Q41: =IF(P41="y",$I$117,0) | R41: =Q41*$C41 | T41: =IF(S41="y",$I$118,0) | U41: =T41*$C41 | W41: =IF(V41="y",$I$119,0) | X41: =W41*$C41 | Z41: =IF(Y41="y",$I$120,0) | AA41: =Z41*$C41 | AC41: =IF(AB41="y",$I$121,0) | AD41: =AC41*$C41 | AF41: =IF(AE41="y",$I$122,0) | AG41: =AF41*$C41 | AH41: =SUM(F41+I41+L41+O41+R41+U41+X41+AA41+AD41+AG41)
...

Sheet Proposal
J2: Proposal # | K2: ='Pricing Worksheet'!I2
J3: Date: | K3: =TODAY()
J4: Project Name: | K4: ='Pricing Worksheet'!C2
J5: Project Address: | K5: ='Pricing Worksheet'!F2
J6: Project Type: | K6: ='Pricing Worksheet'!C4
J7: Architect: | K7: ='Pricing Worksheet'!F4
J8: Contact: | K8: ='Pricing Worksheet'!C3
J9: Phone: | K9: ='Pricing Worksheet'!I3
B10: 6 Aaron Way, Sparta, NJ 07871 O - 862-701-5320 | J10: Email: | K10: ='Pricing Worksheet'!L3
B11: www.glassflooringsystems.com | J11: Quoted By: | K11: ='Pricing Worksheet'!L2
B14: Thank you for your interest in Glass Flooring Systems. The following quote is for (1 Qty.) 18" x 30" Series 1000 SkyFloor® walkable skylight. This are complete systems which consist of our proprietary structural, thermally broken, recessed perimeter framing (modified rear flange removal on all sides) with integrated setting gaskets, perimeter LED lighting channel and one (1) structural walkable glass panel with tested anti-slip top layer. Framing to arrive fully welded, glazing to be performed on site - by others. The make-up of the glass panel is listed below. Please review and let us know if you have any questions or require additional information.
B16: Once you receive your SkyFloor® system all that is required for installation is three simple steps.
B17: 1. Set assembled SkyFloor® system at prepared opening.
B18: 2. Secure assembled SkyFloor® system at prepared opening.
B19: 3. Complete field waterproofing.
B21: Glass Flooring Systems to supply as follows:
B22: Unit | C22: Drawing | D22: Drawing Date | E22: Location | F22: Exposed Frame Dimension (inches) | J22: Description
B23: ='Pricing Worksheet'!D113 | C23: ='Pricing Worksheet'!C113 | D23: 9.27.24 | E23: ='Pricing Worksheet'!B113 | F23: ='Pricing Worksheet'!E113 | G23: x | H23: ='Pricing Worksheet'!F113 | I23: (1 Qty.) 18" x 30" Series 1000 SkyFloor® walkable skylight - consisting of one (1) glass panel
B24: ='Pricing Worksheet'!D114 | C24: ='Pricing Worksheet'!C114 | E24: ='Pricing Worksheet'!B114 | F24: ='Pricing Worksheet'!E114 | G24: x | H24: ='Pricing Worksheet'!F114 | J24: Description
B25: ='Pricing Worksheet'!D115 | C25: ='Pricing Worksheet'!C115 | E25: ='Pricing Worksheet'!B115 | F25: ='Pricing Worksheet'!E115 | G25: x | H25: ='Pricing Worksheet'!F115 | J25: Description
B26: ='Pricing Worksheet'!D116 | C26: ='Pricing Worksheet'!C116 | E26: ='Pricing Worksheet'!B116 | F26: ='Pricing Worksheet'!E116 | G26: x | H26: ='Pricing Worksheet'!F116 | J26: Description
B27: ='Pricing Worksheet'!D117 | C27: ='Pricing Worksheet'!C117 | E27: ='Pricing Worksheet'!B117 | F27: ='Pricing Worksheet'!E117 | G27: x | H27: ='Pricing Worksheet'!F117 | J27: Description
B28: ='Pricing Worksheet'!D118 | C28: ='Pricing Worksheet'!C118 | E28: ='Pricing Worksheet'!B118 | F28: ='Pricing Worksheet'!E118 | G28: x | H28: ='Pricing Worksheet'!F118 | J28: Description
B29: ='Pricing Worksheet'!D119 | C29: ='Pricing Worksheet'!C119 | E29: ='Pricing Worksheet'!B119 | F29: ='Pricing Worksheet'!E119 | G29: x | H29: ='Pricing Worksheet'!F119 | J29: Description
B30: ='Pricing Worksheet'!D120 | C30: ='Pricing Worksheet'!C120 | E30: ='Pricing Worksheet'!B120 | F30: ='Pricing Worksheet'!E120 | G30: x | H30: ='Pricing Worksheet'!F120 | J30: Description
B31: ='Pricing Worksheet'!D121 | C31: ='Pricing Worksheet'!C121 | E31: ='Pricing Worksheet'!B121 | F31: ='Pricing Worksheet'!E121 | G31: x | H31: ='Pricing Worksheet'!F121 | J31: Description
B32: ='Pricing Worksheet'!D122 | C32: ='Pricing Worksheet'!C122 | E32: ='Pricing Worksheet'!B122 | F32: ='Pricing Worksheet'!E122 | G32: x | H32: ='Pricing Worksheet'!F122 | J32: Description
B34: Glazing
B35: Glass Make-up
B36: 10mm top layer – low iron tempered anti-slip texture. Final texture TBD.
B37: 1.52mm interlayer – PVB
B38: 10mm middle layer – low iron tempered
B39: 1.52mm interlayer – PVB
B40: 10mm bottom layer – low iron tempered
B42: Glass Make-up
B43: 10mm top layer – low iron tempered anti-slip texture. Final texture TBD.
B44: 1.52mm interlayer – DG Structural
B45: 10mm middle layer – low iron tempered
B46: 1.52mm interlayer – DG Structural
... B68: Pricing
...

Sheet Proposal Descriptions
A4: Series 1000 Pedestal TB FA | B4: Thank you for your interest in Glass Flooring Systems. The following quote is for (X) XX" x XX" fully assembled ICC approved Series 1000 SkyFloor® walkable skylights. These are complete units which consist of our proprietary, thermally broken structural pedestal framing with integrated setting gasket and structural walkable glass panels with tested anti-slip top layer. They come fully assembled with the walkable glass panels bonded to the frames with Dow Corning 995 silicone. The make up of the glass panels is listed below. Please review and let us know if you have any questions or need any additional information.
A5: Series 1000 Pedestal TB KD | B5: Thank you for your interest in Glass Flooring Systems. The following quote is for (X) XX" x XX" ICC approved Series 1000 SkyFloor® walkable skylights. These are complete systems which consist of our proprietary, thermally broken structural pedestal framing with integrated setting gaskets and structural walkable glass panels with tested anti-slip top layer. The make up of the glass panels is listed below. Please review and let us know if you have any questions or need any additional information.
A6: Series 1000 Recessed TB FA | B6: Thank you for your interest in Glass Flooring Systems. The following quote is for (X) XX" x XX" fully assembled ICC approved Series 1000 SkyFloor® walkable skylights. These are complete units which consist of our proprietary structural, thermally broken, recessed framing with integrated setting gaskets, LED light channel and structural walkable glass panels with tested anti-slip top layer. They come fully assembled with the walkable glass panels bonded to the frames with Dow Corning 995 silicone. The make up of the glass panels is listed below. Please review and let us know if you have any questions or need any additional information.
A7: Series 1000 Recessed TB KD | B7: Thank you for your interest in Glass Flooring Systems. The following quote is for (X) XX" x XX" ICC approved Series 1000 SkyFloor® walkable skylights. These are complete systems which consist of our proprietary structural, thermally broken, recessed framing with integrated setting gaskets and structural walkable glass panels with tested anti-slip top layer. The make up of the glass panels is listed below. Please review and let us know if you have any questions or need any additional information.
A8: Series 1000 Interior Recessed FA | B8: Thank you for your interest in Glass Flooring Systems. The following quote is for (X) XX" x XX" fully assembled SkyFloor® interior glass flooring system. This is a complete system consisting of the walkable glass panels with tested anti-slip texture and our structural recessed interior floor framing with integrated setting gaskets and LED light channel. The make up of the glass panels is listed below. Please review and let us know if you have any questions or need any additional information.
A9: Series 1000 Interior Recessed KD | B9: Thank you for your interest in Glass Flooring Systems. The following quote is for (X) XX" x XX" SkyFloor® interior glass flooring system. This is a complete system consisting of the walkable glass panels with tested anti-slip texture and our structural recessed interior floor framing with integrated setting gaskets and LED light channel. The make up of the glass panels is listed below. Please review and let us know if you have any questions or need any additional information.
A10: EconoFrame and Gasket | B10: Thank you for your interest in Glass Flooring Systems. The following quote is for (X) XX" x XX" walkable glass panels with tested anti-slip top surface. Also, included with the glass panel pricing is a add option for our EconoFrame® with integrated setting gasket. The eFrame will come to you in 12 ft. lengths and will need to be cut to size by installer. Our EconoFrame™ is an easy and elegant solution for setting walkable glass panels onto existing structural framing. The make up of the glass panels is listed below. Please review and let us know if you have any questions or need any additional information.
A11: EconoFrame cut to size | B11: Thank you for your interest in Glass Flooring Systems. The following quote is for (X) XX" x XX" walkable glass panels with tested anti-slip top surface. Also, included with the glass panels is our EconoFrame® cut to size with integrated setting gasket. Our EconoFrame® is an easy and elegant solution for setting walkable glass panels onto existing structural framing. The make up of the glass panels is listed below. Please review and let us know if you have any questions or need any additional information.
A12: Just Glass | B12: Thank you for your interest in Glass Flooring Systems. The following quote is for (X) XX" x XX" walkable glass panels. Each structural walkable glass panels has a tested anti-slip top layer. The make up of the glass panels is listed below. Please review and let us know if you have any questions or need any additional information.
A13: Stair Treads | B13: Thank you for your interest in Glass Flooring Systems. The following quote is for (X) XX" x XX" glass stair treads. All stair tread edges are post lamination polished for an ultra clear finished edge. The make up of the glass treads is listed below. Please review and let us know if you have any questions or need any additional information.
A14: Deck | B14: Thank you for your interest in Glass Flooring Systems. The following quote is for a XX" x XX" SkyFloor® glass deck system. This is a complete deck system consisting of the walkable glass panels with tested anti-slip texture and our structural deck framing with integrated setting gaskets, LED light channel and (xx) linear feet of integrated (glass cable) railing. The make up of the glass panels is listed below. Please review and let us know if you have any questions or need any additional information.
A15: Series 2000 Pedestal TB FA | B15: Thank you for your interest in Glass Flooring Systems. The following quote is for (X) XX" x XX" fully assembled ICC approved Series 2000 SkyFloor® ultra high performance walkable skylights. These are complete units which consist of our proprietary, thermally broken structural pedestal framing with integrated gutter and weep system, setting gaskets and structural walkable glass panels with tested anti-slip top layer. They come fully assembled with the walkable glass panels bonded to the frames with Dow Corning 995 silicone. The make up of the glass panels is listed below. Please review and let us know if you have any questions or need any additional information.
... A29: Interior Recessed Knock Down | B29: 6063-T6 extruded aluminum, interior recessed perimeter framing with integrated LED lighting channel. Unit to be assembled and glazed on site.
B30: 6063-T6 extruded aluminum non-structural EconoFrame® perimeter framing with integrated LED lighting channel. Finish is a painted black. The EconoFrame® is not designed as waterproofed system - please let estimating know if this is a project requirement. This material is available as a fully welded frame at an additional cost.
A31: EconoFrame Cut to Size | B31: 6063-T6 extruded aluminum non-structural EconoFrame® perimeter framing with integrated LED lighting channel. Cut to size. Finish is a painted black. The EconoFrame® is not designed as waterproofed system - please let estimating know if this is a project requirement. This material is available as a fully welded frame at an additional cost.
B32: Framing is not included in this proposal.
B33: Framing is not included in this proposal.
A34: Deck Perimeter | B34: 6063-T6 extruded aluminum, deck perimeter framing with integrated LED lighting channel.
B36: Hide this, frame finish and EconoFrame info - Not being used
B38: Installation by certified Glass Flooring Systems contractor. This will be a separate contract between owner and installer. Add $xxxxx
B39: Initial here ________ if you require installation and approve additional charge as noted.
A42: Typical | B42: Lead time is dependent on the anti-slip texture selected. Currently our lead time is 4 - 5 weeks for in stock textures and 10-12 weeks for textures not currently in stock. Please check with us for availability - Lead times are from approved shop drawings.
A45: Expedited Orders | B45: Lead times are dependent on the anti-slip texture decided upon. Currently, our lead time is 10 - 12 weeks from approved shop drawings. We are able to expedite orders, which contain readily available anti-slip textures, for an additional fee . Expedited orders have a 4-6 week lead time from approved shops.
A49: IGU's (anything from control) | B49: lead time 14 - 16 weeks after approved shop drawings but can vary depending on market conditions. See our terms and conditions for more information.
B51: 10mm top layer – low iron tempered Sevasa anti-slip texture. Final texture TBD.
B52: .060 interlayer PVB
B53: 10mm middle layer – low iron tempered
B54: .060 interlayer PVB
B55: 10mm bottom layer – low iron tempered
A58: Engineering Descriptions
A59: Glass only
A60: Glass and frame
A61: Stamped drawings

Sheet Transmittal
A1: Glass Flooring Systems, Inc.
A2: 6 Aaron Way Sparta, NJ 07871 - Phone (862) 701-5320
B5: Transmittal
I8: Date: | K8: Project #:
B9: Deliver To:
I11: Project:
B13: Attn:
B16: We are sending you
C18: Shop Drawings | F18: Sky Floor™ unit
C20: Frame Sample | F20: Test Unit
C22: Glass Sample | F22: For Review
C24: Specifications | F24: For Approval
C28: Qty | D28: Date | E28: Paint Color | G28: Revisions | H28: Description
C43: Sent by: | D43: Danielle Fisher

Sheet Invoice
J3: Invoice Order # | K3: 10206
J4: Date: | K4: =TODAY()
J5: Project Name: | K5: =#REF!
H6: Project Address: | K6: =#REF!
J7: Contact: | K7: =#REF!
J8: Phone: | K8: =#REF!
J9: Email: | K9: =#REF!
B10: 6 Aaron Way Sparta, NJ 07871
B11: www.glassflooringsystems.com
A15: Invoice Order #10206
C18: =#REF!
C19: =#REF!
C20: Contact person: | E20: =#REF!
C21: Phone: | D21: =#REF!
C30: One 24 x 24 Sky Floor walk on skylight
C39: Thank You for choosing Glass Floor System, Inc.
C41: Greg Muniz
C42: greg@glassflooringsystems.com
A54: www.glassflooringsystems.com
A55: 6 Aaron Way Sparta, NJ 07871
A56: 862-701-5320

Sheet Change Order
B2: Change Order
J4: Change Order # | N4: =#REF! & " CO"
J5: Date: | N5: =TODAY()
J6: Project Name: | N6: =#REF!
J7: Project Address: | N7: =#REF!
J8: Contact: | N8: Dan Muniz
J9: Email: | N9: dan@glassflooringsystems.com
B11: 6 Aaron Way Sparta, NJ 07871
B12: 862-701-5320
B13: www.glassflooringsystems.com
B18: Customer
B19: =#REF!
B20: =#REF!
B21: Attn: | C21: =#REF!
B25: Qty | D25: Description | K25: Price | N25: Amount
K26: 0 | N26: =B26*K26
K27: 0 | N27: =B27*K27
K28: 0 | N28: =B28*K28
K29: 0 | N29: =B29*K29
K30: 0 | N30: =B30*K30
K31: 0 | N31: =B31*K31
K32: 0 | N32: =B32*K32
K33: 0 | N33: =B33*K33
K34: 0 | N34: =B34*K34
K35: 0 | N35: =B35*K35
K36: 0 | N36: =B36*K36
B37: Note: This change order becomes part of and in conformance with the existing contract
E39: We agree to the changes specified above at this price | N39: =SUM(N26:N36)
E40: Previous contract amount | N40: =Proposal!#REF!
E41: Revised contract price | N41: =N40+N39
B48: Accepted - The above prices and specifications of this change order are satisfactory and are hereby accepted. All work to be performed under same terms and conditions as specified in original contract unless otherwise stipulated.
B55: Signature -
B57: Date of acceptance -

Sheet Claim Form
B2: Claim Invoice
J5: Date: | N5: =TODAY()
J6: Project Name: | N6: =#REF!
J7: Project Address: | N7: =#REF!
J8: Contact: | N8: Greg Muniz
J9: Email: | N9: greg@glassflooringsystems.com
M10: Claim #
B11: 6 Aaron Way Sparta, NJ 07981
B12: 862-701-5320
B13: www.glassflooringsystems.com
B18: Customer
B19: =#REF!
B20: =#REF!
B21: Attn: | C21: =#REF!
B25: Qty | D25: Description | K25: Price | N25: Amount
K26: 0 | N26: =B26*K26
K27: 0 | N27: =B27*K27
K28: 0 | N28: =B28*K28
K29: 0 | N29: =B29*K29
K30: 0 | N30: =B30*K30
K31: 0 | N31: =B31*K31
K32: 0 | N32: =B32*K32
K33: 0 | N33: =B33*K33
K34: 0 | N34: =B34*K34
K35: 0 | N35: =B35*K35
K36: 0 | N36: =B36*K36
B37: Note: This change order becomes part of and in conformance with the existing contract
E39: We agree to the changes specified above at this price | N39: =SUM(N26:N36)
E40: Previous contract amount | N40: =Proposal!#REF!
E41: Revised contract price | N41: =N40+N39
B48: Accepted - The above prices and specifications of this change order are satisfactory and are hereby accepted. All work to be performed under same terms and conditions as specified in original contract unless otherwise stipulated.
B55: Signature -
B57: Date of acceptance -

Sheet Purchase Order
A2: Purchase Order
O3: Lucid
I4: Purchase Order # | M4: 11076 | O4: Control
I5: Date: | M5: =TODAY() | O5: Eastern Glass
I6: Project Name: | M6: RoboPac Repair | O6: Quality Metal
I7: Project Address: | O7: Intuitive Powder Coating | P7: Y
I8: Contact: | M8: Greg Muniz | O8: Bonnell
I9: Email: | M9: greg@glassflooringsystems.com | O9: Lauren Manufacturing
O10: Purchase order # | P10: 10141
A11: 6 Aaron Way Sparta, NJ 07871 862-701-5320 | O11: ="Purchase Order #"&P10
A12: www.glassflooringsystems.com
A17: Vendor | J17: Ship To
A18: ROBOPAC USA Valentina Ferrari | J18: Glass Flooring Systems 6 Aaron Way Sparta, NJ 07871 Attn: Greg Muniz 862-701-5320 | O18: Lucid Glass Studio 76 Amarai Street East Providence, Rhode Island 02915 Attn: Clint Hopkins 401-434-1277 | P18: Control Glass, Acustico y Solar, S.L. POL. Ind La Paz, Oporto, 4 44195 Teruel Spain Attn: Alvaro del Rio +34628067281 | Q18: Eastern Glass Resources, Inc. 770 Supor Boulevard Harrison, NJ 07029 Attn: Max Fisher 973-483-8411 | R18: Quality Metal Finishing 80 George Street Paterson, NJ 07503 Attn: Brad 973-345-0963 | S18: Intuitive Powder Coating 100 Hibernia Ave. Rockaway, NJ 07866 Attn: Chris Ruhren 862-432-7851 | T18: Bonnell Aluminum 25 Bonnell Street PO Box 428 Newnan Georgia 30263 Attn: Kristen Avery 615-683-2922 | U18: Lauren Manufacturing 2228 Reiser Ave New Philadelphia, Ohio 44663 Attn: Catherine Moss 330-339-3373
A20: =IF(P3="Y","Clint",IF(P4="Y","Alvaro",IF(P5="Y","Joe","")))
A22: Approval to schedule technician on Thursday 9/15/22 to repair inopperable RoboPac Machine. Quote #412 REV
A42: Thank You
A44: Greg Muniz
A45: greg@glassflooringsystems.com

Sheet Packing List
A1: Glass Flooring Systems, Inc.
A2: 6 Aaron Way Sparta, NJ 07871 - Phone (862) 701-5320
B5: Packing List
H8: Date: | I8: =TODAY() | J8: Project #: | K8: =#REF!
B9: To: | C9: =#REF!
C10: =#REF! | H10: Project Name: | I10: =#REF!
H11: Address: | I11: =#REF!
B13: Attention: | D13: =#REF!
D14: =#REF!
B16: We are sending you
C18: Shop Drawings | F18: Sky Floor™ unit
C20: Paint Sample | E20: X | F20: Test Unit
C22: Glass Sample | F22: For Review
C24: Specifications | F24: For Approval
C28: Qty | D28: Date | E28: Paint Color | G28: Revisions | H28: Description
B56: Sent by: | D56: Greg Muniz

Sheet Weights - Descriptions
A3: Frame | D3: lb./ft. | E3: Unit 1 | F3: Unit 2 | G3: Unit 3 | H3: Unit 4 | I3: Unit 5 | J3: Unit 6 | K3: Unit 7 | L3: Unit 8 | M3: Unit 9 | N3: Unit 10
B4: Perimeter*
B5: Pedestal perimeter thermally broken | C5: GFS-5 | D5: =7.673+D25+D24 | E5: ='Pricing Worksheet'!E37*'Weights - Descriptions'!$D$5 | F5: ='Pricing Worksheet'!H$37*'Weights - Descriptions'!$D$5 | G5: ='Pricing Worksheet'!K$37*'Weights - Descriptions'!$D$5 | H5: ='Pricing Worksheet'!N$37*'Weights - Descriptions'!$D$5 | I5: ='Pricing Worksheet'!Q$37*'Weights - Descriptions'!$D$5 | J5: ='Pricing Worksheet'!T$37*'Weights - Descriptions'!$D$5 | K5: ='Pricing Worksheet'!W$37*'Weights - Descriptions'!$D$5 | L5: ='Pricing Worksheet'!Z$37*'Weights - Descriptions'!$D$5 | M5: ='Pricing Worksheet'!AC$37*'Weights - Descriptions'!$D$5 | N5: ='Pricing Worksheet'!AF$37*'Weights - Descriptions'!$D$5
B6: Recessed perimeter thermally broken | C6: GFS-6 | D6: =8.524+D25+D24 | E6: ='Pricing Worksheet'!E38*'Weights - Descriptions'!$D$6 | F6: ='Pricing Worksheet'!H$38*'Weights - Descriptions'!$D$6 | G6: ='Pricing Worksheet'!K$38*'Weights - Descriptions'!$D$6 | H6: ='Pricing Worksheet'!N$38*'Weights - Descriptions'!$D$6 | I6: ='Pricing Worksheet'!Q$38*'Weights - Descriptions'!$D$6 | J6: ='Pricing Worksheet'!T$38*'Weights - Descriptions'!$D$6 | K6: ='Pricing Worksheet'!W$38*'Weights - Descriptions'!$D$6 | L6: ='Pricing Worksheet'!Z$38*'Weights - Descriptions'!$D$6 | M6: ='Pricing Worksheet'!AC$38*'Weights - Descriptions'!$D$6 | N6: ='Pricing Worksheet'!AF$38*'Weights - Descriptions'!$D$6
B7: Recessed Perimeter non thermally broken | C7: GFS-4 | D7: 7.973 | E7: ='Pricing Worksheet'!E39*'Weights - Descriptions'!$D$7 | F7: ='Pricing Worksheet'!H$39*'Weights - Descriptions'!$D$7 | G7: ='Pricing Worksheet'!K$39*'Weights - Descriptions'!$D$7 | H7: ='Pricing Worksheet'!N$39*'Weights - Descriptions'!$D$7 | I7: ='Pricing Worksheet'!Q$39*'Weights - Descriptions'!$D$7 | J7: ='Pricing Worksheet'!T$39*'Weights - Descriptions'!$D$7 | K7: ='Pricing Worksheet'!W$39*'Weights - Descriptions'!$D$7 | L7: ='Pricing Worksheet'!Z$39*'Weights - Descriptions'!$D$7 | M7: ='Pricing Worksheet'!AC$39*'Weights - Descriptions'!$D$7 | N7: ='Pricing Worksheet'!AF$39*'Weights - Descriptions'!$D$7
B8: Deck perimeter | C8: GFS-13 | D8: 10.297 | E8: ='Pricing Worksheet'!E$44*'Weights - Descriptions'!$D$8 | F8: ='Pricing Worksheet'!H$44*'Weights - Descriptions'!$D$8 | G8: ='Pricing Worksheet'!K$44*'Weights - Descriptions'!$D$8 | H8: ='Pricing Worksheet'!N$44*'Weights - Descriptions'!$D$8 | I8: ='Pricing Worksheet'!Q$44*'Weights - Descriptions'!$D$8 | J8: ='Pricing Worksheet'!T$44*'Weights - Descriptions'!$D$8 | K8: ='Pricing Worksheet'!W$44*'Weights - Descriptions'!$D$8 | L8: ='Pricing Worksheet'!Z$44*'Weights - Descriptions'!$D$8 | M8: ='Pricing Worksheet'!AC$44*'Weights - Descriptions'!$D$8 | N8: ='Pricing Worksheet'!AF$44*'Weights - Descriptions'!$D$8
B9: Series 2000 Pedestal | C9: GFS-15 | D9: 5.785 | E9: ='Pricing Worksheet'!E$40*'Weights - Descriptions'!$D$9 | F9: ='Pricing Worksheet'!H$40*'Weights - Descriptions'!$D$9 | G9: ='Pricing Worksheet'!K$40*'Weights - Descriptions'!$D$9 | H9: ='Pricing Worksheet'!N$40*'Weights - Descriptions'!$D$9 | I9: ='Pricing Worksheet'!Q$40*'Weights - Descriptions'!$D$9 | J9: ='Pricing Worksheet'!T$40*'Weights - Descriptions'!$D$9 | K9: ='Pricing Worksheet'!W$40*'Weights - Descriptions'!$D$9 | L9: ='Pricing Worksheet'!Z$40*'Weights - Descriptions'!$D$9 | M9: ='Pricing Worksheet'!AC$40*'Weights - Descriptions'!$D$9 | N9: ='Pricing Worksheet'!AF$40*'Weights - Descriptions'!$D$9
B10: Series 2000 Recessed | C10: GFS-16 | D10: 6.371 | E10: ='Pricing Worksheet'!E$41*'Weights - Descriptions'!$D$10 | F10: ='Pricing Worksheet'!H$41*'Weights - Descriptions'!$D$10 | G10: ='Pricing Worksheet'!K$41*'Weights - Descriptions'!$D$10 | H10: ='Pricing Worksheet'!N$41*'Weights - Descriptions'!$D$10 | I10: ='Pricing Worksheet'!Q$41*'Weights - Descriptions'!$D$10 | J10: ='Pricing Worksheet'!T$41*'Weights - Descriptions'!$D$10 | K10: ='Pricing Worksheet'!W$41*'Weights - Descriptions'!$D$10 | L10: ='Pricing Worksheet'!Z$41*'Weights - Descriptions'!$D$10 | M10: ='Pricing Worksheet'!AC$41*'Weights - Descriptions'!$D$10 | N10: ='Pricing Worksheet'!AF$41*'Weights - Descriptions'!$D$10
B12: Rafters
B13: T Rafter non-thermal | C13: GFS-1 | D13: 6.77 | E13: ='Pricing Worksheet'!E53*'Weights - Descriptions'!$D$13 | F13: ='Pricing Worksheet'!H$53*'Weights - Descriptions'!$D$13 | G13: ='Pricing Worksheet'!K$53*'Weights - Descriptions'!$D$13 | H13: ='Pricing Worksheet'!N$53*'Weights - Descriptions'!$D$13 | I13: ='Pricing Worksheet'!Q$53*'Weights - Descriptions'!$D$13 | J13: ='Pricing Worksheet'!T$53*'Weights - Descriptions'!$D$13 | K13: ='Pricing Worksheet'!W$53*'Weights - Descriptions'!$D$13 | L13: ='Pricing Worksheet'!Z$53*'Weights - Descriptions'!$D$13 | M13: ='Pricing Worksheet'!AC$53*'Weights - Descriptions'!$D$13 | N13: ='Pricing Worksheet'!AF$53*'Weights - Descriptions'!$D$13
B14: I Rafter non-thermal | C14: GFS-7 | D14: 9.626 | E14: ='Pricing Worksheet'!E54*'Weights - Descriptions'!$D$14 | F14: ='Pricing Worksheet'!H$54*'Weights - Descriptions'!$D$14 | G14: ='Pricing Worksheet'!K$54*'Weights - Descriptions'!$D$14 | H14: ='Pricing Worksheet'!N$54*'Weights - Descriptions'!$D$14 | I14: ='Pricing Worksheet'!Q$54*'Weights - Descriptions'!$D$14 | J14: ='Pricing Worksheet'!T$54*'Weights - Descriptions'!$D$14 | K14: ='Pricing Worksheet'!W$54*'Weights - Descriptions'!$D$14 | L14: ='Pricing Worksheet'!Z$54*'Weights - Descriptions'!$D$14 | M14: ='Pricing Worksheet'!AC$54*'Weights - Descriptions'!$D$14 | N14: ='Pricing Worksheet'!AF$54*'Weights - Descriptions'!$D$14
B15: T Rafter thermally Broken | D15: =D13+D25 | E15: ='Pricing Worksheet'!E51*'Weights - Descriptions'!$D$15 | F15: ='Pricing Worksheet'!H$51*'Weights - Descriptions'!$D$15 | G15: ='Pricing Worksheet'!K$51*'Weights - Descriptions'!$D$15 | H15: ='Pricing Worksheet'!N$51*'Weights - Descriptions'!$D$15 | I15: ='Pricing Worksheet'!Q$51*'Weights - Descriptions'!$D$15 | J15: ='Pricing Worksheet'!T$51*'Weights - Descriptions'!$D$15 | K15: ='Pricing Worksheet'!W$51*'Weights - Descriptions'!$D$15 | L15: ='Pricing Worksheet'!Z$51*'Weights - Descriptions'!$D$15 | M15: ='Pricing Worksheet'!AC$51*'Weights - Descriptions'!$D$15 | N15: ='Pricing Worksheet'!AF$51*'Weights - Descriptions'!$D$15
B16: I Rafter thermally broken | D16: =D14+D25 | E16: ='Pricing Worksheet'!E52*'Weights - Descriptions'!$D$16 | F16: ='Pricing Worksheet'!H$52*'Weights - Descriptions'!$D$16 | G16: ='Pricing Worksheet'!K$52*'Weights - Descriptions'!$D$16 | H16: ='Pricing Worksheet'!N$52*'Weights - Descriptions'!$D$16 | I16: ='Pricing Worksheet'!Q$52*'Weights - Descriptions'!$D$16 | J16: ='Pricing Worksheet'!T$52*'Weights - Descriptions'!$D$16 | K16: ='Pricing Worksheet'!W$52*'Weights - Descriptions'!$D$16 | L16: ='Pricing Worksheet'!Z$52*'Weights - Descriptions'!$D$16 | M16: ='Pricing Worksheet'!AC$52*'Weights - Descriptions'!$D$16 | N16: ='Pricing Worksheet'!AF$52*'Weights - Descriptions'!$D$16
B17: I Beam Series 2000 | C17: GFS-17 | D17: 9.289 | E17: ='Pricing Worksheet'!E$56*'Weights - Descriptions'!$D$17 | F17: ='Pricing Worksheet'!H$56*'Weights - Descriptions'!$D$17 | G17: ='Pricing Worksheet'!K$56*'Weights - Descriptions'!$D$17 | H17: ='Pricing Worksheet'!N$56*'Weights - Descriptions'!$D$17 | I17: ='Pricing Worksheet'!Q$56*'Weights - Descriptions'!$D$17 | J17: ='Pricing Worksheet'!T$56*'Weights - Descriptions'!$D$17 | K17: ='Pricing Worksheet'!W$56*'Weights - Descriptions'!$D$17 | L17: ='Pricing Worksheet'!Z$56*'Weights - Descriptions'!$D$17 | M17: ='Pricing Worksheet'!AC$56*'Weights - Descriptions'!$D$17 | N17: ='Pricing Worksheet'!AF$56*'Weights - Descriptions'!$D$17
B18: T Rafter Series 2000
